fun main() {
    try {
        val result = 10 / 0
    } catch (e: ArithmeticException) {
        println("Error: ${e.message}")
    }
}
